Workbook

Sheet Kalender
A1: Kalender – Jahr ändern: | G1: 2026 | H1: Jahr im gelben Kasten ändern
A3: Januar | B3: Februar | C3: März | D3: April | E3: Mai | F3: Juni
A4: =IF(MONTH(DATE($G$1,1,1))=1,TEXT(DATE($G$1,1,1),"d")&" "&CHOOSE(WEEKDAY(DATE($G$1,1,1),2),"Mo","Di","Mi","Do","Fr","Sa","So")&IFERROR(CHAR(10)&VLOOKUP(DATE($G$1,1,1),Feiertage!$A$2:$B$13,2,FALSE),""),"") -> d Do Neujahr | B4: =IF(MONTH(DATE($G$1,2,1))=2,TEXT(DATE($G$1,2,1),"d")&" "&CHOOSE(WEEKDAY(DATE($G$1,2,1),2),"Mo","Di","Mi","Do","Fr","Sa","So")&IFERROR(CHAR(10)&VLOOKUP(DATE($G$1,2,1),Feiertage!$A$2:$B$13,2,FALSE),""),"") -> d So | C4: =IF(MONTH(DATE($G$1,3,1))=3,TEXT(DATE($G$1,3,1),"d")&" "&CHOOSE(WEEKDAY(DATE($G$1,3,1),2),"Mo","Di","Mi","Do","Fr","Sa","So")&IFERROR(CHAR(10)&VLOOKUP(DATE($G$1,3,1),Feiertage!$A$2:$B$13,2,FALSE),""),"") -> d So | D4: =IF(MONTH(DATE($G$1,4,1))=4,TEXT(DATE($G$1,4,1),"d")&" "&CHOOSE(WEEKDAY(DATE($G$1,4,1),2),"Mo","Di","Mi","Do","Fr","Sa","So")&IFERROR(CHAR(10)&VLOOKUP(DATE($G$1,4,1),Feiertage!$A$2:$B$13,2,FALSE),""),"") -> d Mi | E4: =IF(MONTH(DATE($G$1,5,1))=5,TEXT(DATE($G$1,5,1),"d")&" "&CHOOSE(WEEKDAY(DATE($G$1,5,1),2),"Mo","Di","Mi","Do","Fr","Sa","So")&IFERROR(CHAR(10)&VLOOKUP(DATE($G$1,5,1),Feiertage!$A$2:$B$13,2,FALSE),""),"") -> d Fr Tag der Arbeit | F4: =IF(MONTH(DATE($G$1,6,1))=6,TEXT(DATE($G$1,6,1),"d")&" "&CHOOSE(WEEKDAY(DATE($G$1,6,1),2),"Mo","Di","Mi","Do","Fr","Sa","So")&IFERROR(CHAR(10)&VLOOKUP(DATE($G$1,6,1),Feiertage!$A$2:$B$13,2,FALSE),""),"") -> d Mo
A5: =IF(MONTH(DATE($G$1,1,2))=1,TEXT(DATE($G$1,1,2),"d")&" "&CHOOSE(WEEKDAY(DATE($G$1,1,2),2),"Mo","Di","Mi","Do","Fr","Sa","So")&IFERROR(CHAR(10)&VLOOKUP(DATE($G$1,1,2),Feiertage!$A$2:$B$13,2,FALSE),""),"") -> d Fr | B5: =IF(MONTH(DATE($G$1,2,2))=2,TEXT(DATE($G$1,2,2),"d")&" "&CHOOSE(WEEKDAY(DATE($G$1,2,2),2),"Mo","Di","Mi","Do","Fr","Sa","So")&IFERROR(CHAR(10)&VLOOKUP(DATE($G$1,2,2),Feiertage!$A$2:$B$13,2,FALSE),""),"") -> d Mo | C5: =IF(MONTH(DATE($G$1,3,2))=3,TEXT(DATE($G$1,3,2),"d")&" "&CHOOSE(WEEKDAY(DATE($G$1,3,2),2),"Mo","Di","Mi","Do","Fr","Sa","So")&IFERROR(CHAR(10)&VLOOKUP(DATE($G$1,3,2),Feiertage!$A$2:$B$13,2,FALSE),""),"") -> d Mo | D5: =IF(MONTH(DATE($G$1,4,2))=4,TEXT(DATE($G$1,4,2),"d")&" "&CHOOSE(WEEKDAY(DATE($G$1,4,2),2),"Mo","Di","Mi","Do","Fr","Sa","So")&IFERROR(CHAR(10)&VLOOKUP(DATE($G$1,4,2),Feiertage!$A$2:$B$13,2,FALSE),""),"") -> d Do | E5: =IF(MONTH(DATE($G$1,5,2))=5,TEXT(DATE($G$1,5,2),"d")&" "&CHOOSE(WEEKDAY(DATE($G$1,5,2),2),"Mo","Di","Mi","Do","Fr","Sa","So")&IFERROR(CHAR(10)&VLOOKUP(DATE($G$1,5,2),Feiertage!$A$2:$B$13,2,FALSE),""),"") -> d Sa | F5: =IF(MONTH(DATE($G$1,6,2))=6,TEXT(DATE($G$1,6,2),"d")&" "&CHOOSE(WEEKDAY(DATE($G$1,6,2),2),"Mo","Di","Mi","Do","Fr","Sa","So")&IFERROR(CHAR(10)&VLOOKUP(DATE($G$1,6,2),Feiertage!$A$2:$B$13,2,FALSE),""),"") -> d Di
A6: =IF(MONTH(DATE($G$1,1,3))=1,TEXT(DATE($G$1,1,3),"d")&" "&CHOOSE(WEEKDAY(DATE($G$1,1,3),2),"Mo","Di","Mi","Do","Fr","Sa","So")&IFERROR(CHAR(10)&VLOOKUP(DATE($G$1,1,3),Feiertage!$A$2:$B$13,2,FALSE),""),"") -> d Sa | B6: =IF(MONTH(DATE($G$1,2,3))=2,TEXT(DATE($G$1,2,3),"d")&" "&CHOOSE(WEEKDAY(DATE($G$1,2,3),2),"Mo","Di","Mi","Do","Fr","Sa","So")&IFERROR(CHAR(10)&VLOOKUP(DATE($G$1,2,3),Feiertage!$A$2:$B$13,2,FALSE),""),"") -> d Di | C6: =IF(MONTH(DATE($G$1,3,3))=3,TEXT(DATE($G$1,3,3),"d")&" "&CHOOSE(WEEKDAY(DATE($G$1,3,3),2),"Mo","Di","Mi","Do","Fr","Sa","So")&IFERROR(CHAR(10)&VLOOKUP(DATE($G$1,3,3),Feiertage!$A$2:$B$13,2,FALSE),""),"") -> d Di | D6: =IF(MONTH(DATE($G$1,4,3))=4,TEXT(DATE($G$1,4,3),"d")&" "&CHOOSE(WEEKDAY(DATE($G$1,4,3),2),"Mo","Di","Mi","Do","Fr","Sa","So")&IFERROR(CHAR(10)&VLOOKUP(DATE($G$1,4,3),Feiertage!$A$2:$B$13,2,FALSE),""),"") -> d Fr Karfreitag | E6: =IF(MONTH(DATE($G$1,5,3))=5,TEXT(DATE($G$1,5,3),"d")&" "&CHOOSE(WEEKDAY(DATE($G$1,5,3),2),"Mo","Di","Mi","Do","Fr","Sa","So")&IFERROR(CHAR(10)&VLOOKUP(DATE($G$1,5,3),Feiertage!$A$2:$B$13,2,FALSE),""),"") -> d So | F6: =IF(MONTH(DATE($G$1,6,3))=6,TEXT(DATE($G$1,6,3),"d")&" "&CHOOSE(WEEKDAY(DATE($G$1,6,3),2),"Mo","Di","Mi","Do","Fr","Sa","So")&IFERROR(CHAR(10)&VLOOKUP(DATE($G$1,6,3),Feiertage!$A$2:$B$13,2,FALSE),""),"") -> d Mi
A7: =IF(MONTH(DATE($G$1,1,4))=1,TEXT(DATE($G$1,1,4),"d")&" "&CHOOSE(WEEKDAY(DATE($G$1,1,4),2),"Mo","Di","Mi","Do","Fr","Sa","So")&IFERROR(CHAR(10)&VLOOKUP(DATE($G$1,1,4),Feiertage!$A$2:$B$13,2,FALSE),""),"") -> d So | B7: =IF(MONTH(DATE($G$1,2,4))=2,TEXT(DATE($G$1,2,4),"d")&" "&CHOOSE(WEEKDAY(DATE($G$1,2,4),2),"Mo","Di","Mi","Do","Fr","Sa","So")&IFERROR(CHAR(10)&VLOOKUP(DATE($G$1,2,4),Feiertage!$A$2:$B$13,2,FALSE),""),"") -> d Mi | C7: =IF(MONTH(DATE($G$1,3,4))=3,TEXT(DATE($G$1,3,4),"d")&" "&CHOOSE(WEEKDAY(DATE($G$1,3,4),2),"Mo","Di","Mi","Do","Fr","Sa","So")&IFERROR(CHAR(10)&VLOOKUP(DATE($G$1,3,4),Feiertage!$A$2:$B$13,2,FALSE),""),"") -> d Mi | D7: =IF(MONTH(DATE($G$1,4,4))=4,TEXT(DATE($G$1,4,4),"d")&" "&CHOOSE(WEEKDAY(DATE($G$1,4,4),2),"Mo","Di","Mi","Do","Fr","Sa","So")&IFERROR(CHAR(10)&VLOOKUP(DATE($G$1,4,4),Feiertage!$A$2:$B$13,2,FALSE),""),"") -> d Sa | E7: =IF(MONTH(DATE($G$1,5,4))=5,TEXT(DATE($G$1,5,4),"d")&" "&CHOOSE(WEEKDAY(DATE($G$1,5,4),2),"Mo","Di","Mi","Do","Fr","Sa","So")&IFERROR(CHAR(10)&VLOOKUP(DATE($G$1,5,4),Feiertage!$A$2:$B$13,2,FALSE),""),"") -> d Mo | F7: =IF(MONTH(DATE($G$1,6,4))=6,TEXT(DATE($G$1,6,4),"d")&" "&CHOOSE(WEEKDAY(DATE($G$1,6,4),2),"Mo","Di","Mi","Do","Fr","Sa","So")&IFERROR(CHAR(10)&VLOOKUP(DATE($G$1,6,4),Feiertage!$A$2:$B$13,2,FALSE),""),"") -> d Do
A8: =IF(MONTH(DATE($G$1,1,5))=1,TEXT(DATE($G$1,1,5),"d")&" "&CHOOSE(WEEKDAY(DATE($G$1,1,5),2),"Mo","Di","Mi","Do","Fr","Sa","So")&IFERROR(CHAR(10)&VLOOKUP(DATE($G$1,1,5),Feiertage!$A$2:$B$13,2,FALSE),""),"") -> d Mo | B8: =IF(MONTH(DATE($G$1,2,5))=2,TEXT(DATE($G$1,2,5),"d")&" "&CHOOSE(WEEKDAY(DATE($G$1,2,5),2),"Mo","Di","Mi","Do","Fr","Sa","So")&IFERROR(CHAR(10)&VLOOKUP(DATE($G$1,2,5),Feiertage!$A$2:$B$13,2,FALSE),""),"") -> d Do | C8: =IF(MONTH(DATE($G$1,3,5))=3,TEXT(DATE($G$1,3,5),"d")&" "&CHOOSE(WEEKDAY(DATE($G$1,3,5),2),"Mo","Di","Mi","Do","Fr","Sa","So")&IFERROR(CHAR(10)&VLOOKUP(DATE($G$1,3,5),Feiertage!$A$2:$B$13,2,FALSE),""),"") -> d Do | D8: =IF(MONTH(DATE($G$1,4,5))=4,TEXT(DATE($G$1,4,5),"d")&" "&CHOOSE(WEEKDAY(DATE($G$1,4,5),2),"Mo","Di","Mi","Do","Fr","Sa","So")&IFERROR(CHAR(10)&VLOOKUP(DATE($G$1,4,5),Feiertage!$A$2:$B$13,2,FALSE),""),"") -> d So Ostern | E8: =IF(MONTH(DATE($G$1,5,5))=5,TEXT(DATE($G$1,5,5),"d")&" "&CHOOSE(WEEKDAY(DATE($G$1,5,5),2),"Mo","Di","Mi","Do","Fr","Sa","So")&IFERROR(CHAR(10)&VLOOKUP(DATE($G$1,5,5),Feiertage!$A$2:$B$13,2,FALSE),""),"") -> d Di | F8: =IF(MONTH(DATE($G$1,6,5))=6,TEXT(DATE($G$1,6,5),"d")&" "&CHOOSE(WEEKDAY(DATE($G$1,6,5),2),"Mo","Di","Mi","Do","Fr","Sa","So")&IFERROR(CHAR(10)&VLOOKUP(DATE($G$1,6,5),Feiertage!$A$2:$B$13,2,FALSE),""),"") -> d Fr
A9: =IF(MONTH(DATE($G$1,1,6))=1,TEXT(DATE($G$1,1,6),"d")&" "&CHOOSE(WEEKDAY(DATE($G$1,1,6),2),"Mo","Di","Mi","Do","Fr","Sa","So")&IFERROR(CHAR(10)&VLOOKUP(DATE($G$1,1,6),Feiertage!$A$2:$B$13,2,FALSE),""),"") -> d Di | B9: =IF(MONTH(DATE($G$1,2,6))=2,TEXT(DATE($G$1,2,6),"d")&" "&CHOOSE(WEEKDAY(DATE($G$1,2,6),2),"Mo","Di","Mi","Do","Fr","Sa","So")&IFERROR(CHAR(10)&VLOOKUP(DATE($G$1,2,6),Feiertage!$A$2:$B$13,2,FALSE),""),"") -> d Fr | C9: =IF(MONTH(DATE($G$1,3,6))=3,TEXT(DATE($G$1,3,6),"d")&" "&CHOOSE(WEEKDAY(DATE($G$1,3,6),2),"Mo","Di","Mi","Do","Fr","Sa","So")&IFERROR(CHAR(10)&VLOOKUP(DATE($G$1,3,6),Feiertage!$A$2:$B$13,2,FALSE),""),"") -> d Fr | D9: =IF(MONTH(DATE($G$1,4,6))=4,TEXT(DATE($G$1,4,6),"d")&" "&CHOOSE(WEEKDAY(DATE($G$1,4,6),2),"Mo","Di","Mi","Do","Fr","Sa","So")&IFERROR(CHAR(10)&VLOOKUP(DATE($G$1,4,6),Feiertage!$A$2:$B$13,2,FALSE),""),"") -> d Mo Ostermontag | E9: =IF(MONTH(DATE($G$1,5,6))=5,TEXT(DATE($G$1,5,6),"d")&" "&CHOOSE(WEEKDAY(DATE($G$1,5,6),2),"Mo","Di","Mi","Do","Fr","Sa","So")&IFERROR(CHAR(10)&VLOOKUP(DATE($G$1,5,6),Feiertage!$A$2:$B$13,2,FALSE),""),"") -> d Mi | F9: =IF(MONTH(DATE($G$1,6,6))=6,TEXT(DATE($G$1,6,6),"d")&" "&CHOOSE(WEEKDAY(DATE($G$1,6,6),2),"Mo","Di","Mi","Do","Fr","Sa","So")&IFERROR(CHAR(10)&VLOOKUP(DATE($G$1,6,6),Feiertage!$A$2:$B$13,2,FALSE),""),"") -> d Sa
A10: =IF(MONTH(DATE($G$1,1,7))=1,TEXT(DATE($G$1,1,7),"d")&" "&CHOOSE(WEEKDAY(DATE($G$1,1,7),2),"Mo","Di","Mi","Do","Fr","Sa","So")&IFERROR(CHAR(10)&VLOOKUP(DATE($G$1,1,7),Feiertage!$A$2:$B$13,2,FALSE),""),"") -> d Mi | B10: =IF(MONTH(DATE($G$1,2,7))=2,TEXT(DATE($G$1,2,7),"d")&" "&CHOOSE(WEEKDAY(DATE($G$1,2,7),2),"Mo","Di","Mi","Do","Fr","Sa","So")&IFERROR(CHAR(10)&VLOOKUP(DATE($G$1,2,7),Feiertage!$A$2:$B$13,2,FALSE),""),"") -> d Sa | C10: =IF(MONTH(DATE($G$1,3,7))=3,TEXT(DATE($G$1,3,7),"d")&" "&CHOOSE(WEEKDAY(DATE($G$1,3,7),2),"Mo","Di","Mi","Do","Fr","Sa","So")&IFERROR(CHAR(10)&VLOOKUP(DATE($G$1,3,7),Feiertage!$A$2:$B$13,2,FALSE),""),"") -> d Sa | D10: =IF(MONTH(DATE($G$1,4,7))=4,TEXT(DATE($G$1,4,7),"d")&" "&CHOOSE(WEEKDAY(DATE($G$1,4,7),2),"Mo","Di","Mi","Do","Fr","Sa","So")&IFERROR(CHAR(10)&VLOOKUP(DATE($G$1,4,7),Feiertage!$A$2:$B$13,2,FALSE),""),"") -> d Di | E10: =IF(MONTH(DATE($G$1,5,7))=5,TEXT(DATE($G$1,5,7),"d")&" "&CHOOSE(WEEKDAY(DATE($G$1,5,7),2),"Mo","Di","Mi","Do","Fr","Sa","So")&IFERROR(CHAR(10)&VLOOKUP(DATE($G$1,5,7),Feiertage!$A$2:$B$13,2,FALSE),""),"") -> d Do | F10: =IF(MONTH(DATE($G$1,6,7))=6,TEXT(DATE($G$1,6,7),"d")&" "&CHOOSE(WEEKDAY(DATE($G$1,6,7),2),"Mo","Di","Mi","Do","Fr","Sa","So")&IFERROR(CHAR(10)&VLOOKUP(DATE($G$1,6,7),Feiertage!$A$2:$B$13,2,FALSE),""),"") -> d So
A11: =IF(MONTH(DATE($G$1,1,8))=1,TEXT(DATE($G$1,1,8),"d")&" "&CHOOSE(WEEKDAY(DATE($G$1,1,8),2),"Mo","Di","Mi","Do","Fr","Sa","So")&IFERROR(CHAR(10)&VLOOKUP(DATE($G$1,1,8),Feiertage!$A$2:$B$13,2,FALSE),""),"") -> d Do | B11: =IF(MONTH(DATE($G$1,2,8))=2,TEXT(DATE($G$1,2,8),"d")&" "&CHOOSE(WEEKDAY(DATE($G$1,2,8),2),"Mo","Di","Mi","Do","Fr","Sa","So")&IFERROR(CHAR(10)&VLOOKUP(DATE($G$1,2,8),Feiertage!$A$2:$B$13,2,FALSE),""),"") -> d So | C11: =IF(MONTH(DATE($G$1,3,8))=3,TEXT(DATE($G$1,3,8),"d")&" "&CHOOSE(WEEKDAY(DATE($G$1,3,8),2),"Mo","Di","Mi","Do","Fr","Sa","So")&IFERROR(CHAR(10)&VLOOKUP(DATE($G$1,3,8),Feiertage!$A$2:$B$13,2,FALSE),""),"") -> d So | D11: =IF(MONTH(DATE($G$1,4,8))=4,TEXT(DATE($G$1,4,8),"d")&" "&CHOOSE(WEEKDAY(DATE($G$1,4,8),2),"Mo","Di","Mi","Do","Fr","Sa","So")&IFERROR(CHAR(10)&VLOOKUP(DATE($G$1,4,8),Feiertage!$A$2:$B$13,2,FALSE),""),"") -> d Mi | E11: =IF(MONTH(DATE($G$1,5,8))=5,TEXT(DATE($G$1,5,8),"d")&" "&CHOOSE(WEEKDAY(DATE($G$1,5,8),2),"Mo","Di","Mi","Do","Fr","Sa","So")&IFERROR(CHAR(10)&VLOOKUP(DATE($G$1,5,8),Feiertage!$A$2:$B$13,2,FALSE),""),"") -> d Fr | F11: =IF(MONTH(DATE($G$1,6,8))=6,TEXT(DATE($G$1,6,8),"d")&" "&CHOOSE(WEEKDAY(DATE($G$1,6,8),2),"Mo","Di","Mi","Do","Fr","Sa","So")&IFERROR(CHAR(10)&VLOOKUP(DATE($G$1,6,8),Feiertage!$A$2:$B$13,2,FALSE),""),"") -> d Mo
A12: =IF(MONTH(DATE($G$1,1,9))=1,TEXT(DATE($G$1,1,9),"d")&" "&CHOOSE(WEEKDAY(DATE($G$1,1,9),2),"Mo","Di","Mi","Do","Fr","Sa","So")&IFERROR(CHAR(10)&VLOOKUP(DATE($G$1,1,9),Feiertage!$A$2:$B$13,2,FALSE),""),"") -> d Fr | B12: =IF(MONTH(DATE($G$1,2,9))=2,TEXT(DATE($G$1,2,9),"d")&" "&CHOOSE(WEEKDAY(DATE($G$1,2,9),2),"Mo","Di","Mi","Do","Fr","Sa","So")&IFERROR(CHAR(10)&VLOOKUP(DATE($G$1,2,9),Feiertage!$A$2:$B$13,2,FALSE),""),"") -> d Mo | C12: =IF(MONTH(DATE($G$1,3,9))=3,TEXT(DATE($G$1,3,9),"d")&" "&CHOOSE(WEEKDAY(DATE($G$1,3,9),2),"Mo","Di","Mi","Do","Fr","Sa","So")&IFERROR(CHAR(10)&VLOOKUP(DATE($G$1,3,9),Feiertage!$A$2:$B$13,2,FALSE),""),"") -> d Mo | D12: =IF(MONTH(DATE($G$1,4,9))=4,TEXT(DATE($G$1,4,9),"d")&" "&CHOOSE(WEEKDAY(DATE($G$1,4,9),2),"Mo","Di","Mi","Do","Fr","Sa","So")&IFERROR(CHAR(10)&VLOOKUP(DATE($G$1,4,9),Feiertage!$A$2:$B$13,2,FALSE),""),"") -> d Do | E12: =IF(MONTH(DATE($G$1,5,9))=5,TEXT(DATE($G$1,5,9),"d")&" "&CHOOSE(WEEKDAY(DATE($G$1,5,9),2),"Mo","Di","Mi","Do","Fr","Sa","So")&IFERROR(CHAR(10)&VLOOKUP(DATE($G$1,5,9),Feiertage!$A$2:$B$13,2,FALSE),""),"") -> d Sa | F12: =IF(MONTH(DATE($G$1,6,9))=6,TEXT(DATE($G$1,6,9),"d")&" "&CHOOSE(WEEKDAY(DATE($G$1,6,9),2),"Mo","Di","Mi","Do","Fr","Sa","So")&IFERROR(CHAR(10)&VLOOKUP(DATE($G$1,6,9),Feiertage!$A$2:$B$13,2,FALSE),""),"") -> d Di
A13: =IF(MONTH(DATE($G$1,1,10))=1,TEXT(DATE($G$1,1,10),"d")&" "&CHOOSE(WEEKDAY(DATE($G$1,1,10),2),"Mo","Di","Mi","Do","Fr","Sa","So")&IFERROR(CHAR(10)&VLOOKUP(DATE($G$1,1,10),Feiertage!$A$2:$B$13,2,FALSE),""),"") -> d Sa | B13: =IF(MONTH(DATE($G$1,2,10))=2,TEXT(DATE($G$1,2,10),"d")&" "&CHOOSE(WEEKDAY(DATE($G$1,2,10),2),"Mo","Di","Mi","Do","Fr","Sa","So")&IFERROR(CHAR(10)&VLOOKUP(DATE($G$1,2,10),Feiertage!$A$2:$B$13,2,FALSE),""),"") -> d Di | C13: =IF(MONTH(DATE($G$1,3,10))=3,TEXT(DATE($G$1,3,10),"d")&" "&CHOOSE(WEEKDAY(DATE($G$1,3,10),2),"Mo","Di","Mi","Do","Fr","Sa","So")&IFERROR(CHAR(10)&VLOOKUP(DATE($G$1,3,10),Feiertage!$A$2:$B$13,2,FALSE),""),"") -> d Di | D13: =IF(MONTH(DATE($G$1,4,10))=4,TEXT(DATE($G$1,4,10),"d")&" "&CHOOSE(WEEKDAY(DATE($G$1,4,10),2),"Mo","Di","Mi","Do","Fr","Sa","So")&IFERROR(CHAR(10)&VLOOKUP(DATE($G$1,4,10),Feiertage!$A$2:$B$13,2,FALSE),""),"") -> d Fr | E13: =IF(MONTH(DATE($G$1,5,10))=5,TEXT(DATE($G$1,5,10),"d")&" "&CHOOSE(WEEKDAY(DATE($G$1,5,10),2),"Mo","Di","Mi","Do","Fr","Sa","So")&IFERROR(CHAR(10)&VLOOKUP(DATE($G$1,5,10),Feiertage!$A$2:$B$13,2,FALSE),""),"") -> d So | F13: =IF(MONTH(DATE($G$1,6,10))=6,TEXT(DATE($G$1,6,10),"d")&" "&CHOOSE(WEEKDAY(DATE($G$1,6,10),2),"Mo","Di","Mi","Do","Fr","Sa","So")&IFERROR(CHAR(10)&VLOOKUP(DATE($G$1,6,10),Feiertage!$A$2:$B$13,2,FALSE),""),"") -> d Mi
A14: =IF(MONTH(DATE($G$1,1,11))=1,TEXT(DATE($G$1,1,11),"d")&" "&CHOOSE(WEEKDAY(DATE($G$1,1,11),2),"Mo","Di","Mi","Do","Fr","Sa","So")&IFERROR(CHAR(10)&VLOOKUP(DATE($G$1,1,11),Feiertage!$A$2:$B$13,2,FALSE),""),"") -> d So | B14: =IF(MONTH(DATE($G$1,2,11))=2,TEXT(DATE($G$1,2,11),"d")&" "&CHOOSE(WEEKDAY(DATE($G$1,2,11),2),"Mo","Di","Mi","Do","Fr","Sa","So")&IFERROR(CHAR(10)&VLOOKUP(DATE($G$1,2,11),Feiertage!$A$2:$B$13,2,FALSE),""),"") -> d Mi | C14: =IF(MONTH(DATE($G$1,3,11))=3,TEXT(DATE($G$1,3,11),"d")&" "&CHOOSE(WEEKDAY(DATE($G$1,3,11),2),"Mo","Di","Mi","Do","Fr","Sa","So")&IFERROR(CHAR(10)&VLOOKUP(DATE($G$1,3,11),Feiertage!$A$2:$B$13,2,FALSE),""),"") -> d Mi | D14: =IF(MONTH(DATE($G$1,4,11))=4,TEXT(DATE($G$1,4,11),"d")&" "&CHOOSE(WEEKDAY(DATE($G$1,4,11),2),"Mo","Di","Mi","Do","Fr","Sa","So")&IFERROR(CHAR(10)&VLOOKUP(DATE($G$1,4,11),Feiertage!$A$2:$B$13,2,FALSE),""),"") -> d Sa | E14: =IF(MONTH(DATE($G$1,5,11))=5,TEXT(DATE($G$1,5,11),"d")&" "&CHOOSE(WEEKDAY(DATE($G$1,5,11),2),"Mo","Di","Mi","Do","Fr","Sa","So")&IFERROR(CHAR(10)&VLOOKUP(DATE($G$1,5,11),Feiertage!$A$2:$B$13,2,FALSE),""),"") -> d Mo | F14: =IF(MONTH(DATE($G$1,6,11))=6,TEXT(DATE($G$1,6,11),"d")&" "&CHOOSE(WEEKDAY(DATE($G$1,6,11),2),"Mo","Di","Mi","Do","Fr","Sa","So")&IFERROR(CHAR(10)&VLOOKUP(DATE($G$1,6,11),Feiertage!$A$2:$B$13,2,FALSE),""),"") -> d Do
A15: =IF(MONTH(DATE($G$1,1,12))=1,TEXT(DATE($G$1,1,12),"d")&" "&CHOOSE(WEEKDAY(DATE($G$1,1,12),2),"Mo","Di","Mi","Do","Fr","Sa","So")&IFERROR(CHAR(10)&VLOOKUP(DATE($G$1,1,12),Feiertage!$A$2:$B$13,2,FALSE),""),"") -> d Mo | B15: =IF(MONTH(DATE($G$1,2,12))=2,TEXT(DATE($G$1,2,12),"d")&" "&CHOOSE(WEEKDAY(DATE($G$1,2,12),2),"Mo","Di","Mi","Do","Fr","Sa","So")&IFERROR(CHAR(10)&VLOOKUP(DATE($G$1,2,12),Feiertage!$A$2:$B$13,2,FALSE),""),"") -> d Do | C15: =IF(MONTH(DATE($G$1,3,12))=3,TEXT(DATE($G$1,3,12),"d")&" "&CHOOSE(WEEKDAY(DATE($G$1,3,12),2),"Mo","Di","Mi","Do","Fr","Sa","So")&IFERROR(CHAR(10)&VLOOKUP(DATE($G$1,3,12),Feiertage!$A$2:$B$13,2,FALSE),""),"") -> d Do | D15: =IF(MONTH(DATE($G$1,4,12))=4,TEXT(DATE($G$1,4,12),"d")&" "&CHOOSE(WEEKDAY(DATE($G$1,4,12),2),"Mo","Di","Mi","Do","Fr","Sa","So")&IFERROR(CHAR(10)&VLOOKUP(DATE($G$1,4,12),Feiertage!$A$2:$B$13,2,FALSE),""),"") -> d So | E15: =IF(MONTH(DATE($G$1,5,12))=5,TEXT(DATE($G$1,5,12),"d")&" "&CHOOSE(WEEKDAY(DATE($G$1,5,12),2),"Mo","Di","Mi","Do","Fr","Sa","So")&IFERROR(CHAR(10)&VLOOKUP(DATE($G$1,5,12),Feiertage!$A$2:$B$13,2,FALSE),""),"") -> d Di | F15: =IF(MONTH(DATE($G$1,6,12))=6,TEXT(DATE($G$1,6,12),"d")&" "&CHOOSE(WEEKDAY(DATE($G$1,6,12),2),"Mo","Di","Mi","Do","Fr","Sa","So")&IFERROR(CHAR(10)&VLOOKUP(DATE($G$1,6,12),Feiertage!$A$2:$B$13,2,FALSE),""),"") -> d Fr
A16: =IF(MONTH(DATE($G$1,1,13))=1,TEXT(DATE($G$1,1,13),"d")&" "&CHOOSE(WEEKDAY(DATE($G$1,1,13),2),"Mo","Di","Mi","Do","Fr","Sa","So")&IFERROR(CHAR(10)&VLOOKUP(DATE($G$1,1,13),Feiertage!$A$2:$B$13,2,FALSE),""),"") -> d Di | B16: =IF(MONTH(DATE($G$1,2,13))=2,TEXT(DATE($G$1,2,13),"d")&" "&CHOOSE(WEEKDAY(DATE($G$1,2,13),2),"Mo","Di","Mi","Do","Fr","Sa","So")&IFERROR(CHAR(10)&VLOOKUP(DATE($G$1,2,13),Feiertage!$A$2:$B$13,2,FALSE),""),"") -> d Fr | C16: =IF(MONTH(DATE($G$1,3,13))=3,TEXT(DATE($G$1,3,13),"d")&" "&CHOOSE(WEEKDAY(DATE($G$1,3,13),2),"Mo","Di","Mi","Do","Fr","Sa","So")&IFERROR(CHAR(10)&VLOOKUP(DATE($G$1,3,13),Feiertage!$A$2:$B$13,2,FALSE),""),"") -> d Fr | D16: =IF(MONTH(DATE($G$1,4,13))=4,TEXT(DATE($G$1,4,13),"d")&" "&CHOOSE(WEEKDAY(DATE($G$1,4,13),2),"Mo","Di","Mi","Do","Fr","Sa","So")&IFERROR(CHAR(10)&VLOOKUP(DATE($G$1,4,13),Feiertage!$A$2:$B$13,2,FALSE),""),"") -> d Mo | E16: =IF(MONTH(DATE($G$1,5,13))=5,TEXT(DATE($G$1,5,13),"d")&" "&CHOOSE(WEEKDAY(DATE($G$1,5,13),2),"Mo","Di","Mi","Do","Fr","Sa","So")&IFERROR(CHAR(10)&VLOOKUP(DATE($G$1,5,13),Feiertage!$A$2:$B$13,2,FALSE),""),"") -> d Mi | F16: =IF(MONTH(DATE($G$1,6,13))=6,TEXT(DATE($G$1,6,13),"d")&" "&CHOOSE(WEEKDAY(DATE($G$1,6,13),2),"Mo","Di","Mi","Do","Fr","Sa","So")&IFERROR(CHAR(10)&VLOOKUP(DATE($G$1,6,13),Feiertage!$A$2:$B$13,2,FALSE),""),"") -> d Sa
A17: =IF(MONTH(DATE($G$1,1,14))=1,TEXT(DATE($G$1,1,14),"d")&" "&CHOOSE(WEEKDAY(DATE($G$1,1,14),2),"Mo","Di","Mi","Do","Fr","Sa","So")&IFERROR(CHAR(10)&VLOOKUP(DATE($G$1,1,14),Feiertage!$A$2:$B$13,2,FALSE),""),"") -> d Mi | B17: =IF(MONTH(DATE($G$1,2,14))=2,TEXT(DATE($G$1,2,14),"d")&" "&CHOOSE(WEEKDAY(DATE($G$1,2,14),2),"Mo","Di","Mi","Do","Fr","Sa","So")&IFERROR(CHAR(10)&VLOOKUP(DATE($G$1,2,14),Feiertage!$A$2:$B$13,2,FALSE),""),"") -> d Sa | C17: =IF(MONTH(DATE($G$1,3,14))=3,TEXT(DATE($G$1,3,14),"d")&" "&CHOOSE(WEEKDAY(DATE($G$1,3,14),2),"Mo","Di","Mi","Do","Fr","Sa","So")&IFERROR(CHAR(10)&VLOOKUP(DATE($G$1,3,14),Feiertage!$A$2:$B$13,2,FALSE),""),"") -> d Sa | D17: =IF(MONTH(DATE($G$1,4,14))=4,TEXT(DATE($G$1,4,14),"d")&" "&CHOOSE(WEEKDAY(DATE($G$1,4,14),2),"Mo","Di","Mi","Do","Fr","Sa","So")&IFERROR(CHAR(10)&VLOOKUP(DATE($G$1,4,14),Feiertage!$A$2:$B$13,2,FALSE),""),"") -> d Di | E17: =IF(MONTH(DATE($G$1,5,14))=5,TEXT(DATE($G$1,5,14),"d")&" "&CHOOSE(WEEKDAY(DATE($G$1,5,14),2),"Mo","Di","Mi","Do","Fr","Sa","So")&IFERROR(CHAR(10)&VLOOKUP(DATE($G$1,5,14),Feiertage!$A$2:$B$13,2,FALSE),""),"") -> d Do Christi Himmelfahrt | F17: =IF(MONTH(DATE($G$1,6,14))=6,TEXT(DATE($G$1,6,14),"d")&" "&CHOOSE(WEEKDAY(DATE($G$1,6,14),2),"Mo","Di","Mi","Do","Fr","Sa","So")&IFERROR(CHAR(10)&VLOOKUP(DATE($G$1,6,14),Feiertage!$A$2:$B$13,2,FALSE),""),"") -> d So
A18: =IF(MONTH(DATE($G$1,1,15))=1,TEXT(DATE($G$1,1,15),"d")&" "&CHOOSE(WEEKDAY(DATE($G$1,1,15),2),"Mo","Di","Mi","Do","Fr","Sa","So")&IFERROR(CHAR(10)&VLOOKUP(DATE($G$1,1,15),Feiertage!$A$2:$B$13,2,FALSE),""),"") -> d Do | B18: =IF(MONTH(DATE($G$1,2,15))=2,TEXT(DATE($G$1,2,15),"d")&" "&CHOOSE(WEEKDAY(DATE($G$1,2,15),2),"Mo","Di","Mi","Do","Fr","Sa","So")&IFERROR(CHAR(10)&VLOOKUP(DATE($G$1,2,15),Feiertage!$A$2:$B$13,2,FALSE),""),"") -> d So | C18: =IF(MONTH(DATE($G$1,3,15))=3,TEXT(DATE($G$1,3,15),"d")&" "&CHOOSE(WEEKDAY(DATE($G$1,3,15),2),"Mo","Di","Mi","Do","Fr","Sa","So")&IFERROR(CHAR(10)&VLOOKUP(DATE($G$1,3,15),Feiertage!$A$2:$B$13,2,FALSE),""),"") -> d So | D18: =IF(MONTH(DATE($G$1,4,15))=4,TEXT(DATE($G$1,4,15),"d")&" "&CHOOSE(WEEKDAY(DATE($G$1,4,15),2),"Mo","Di","Mi","Do","Fr","Sa","So")&IFERROR(CHAR(10)&VLOOKUP(DATE($G$1,4,15),Feiertage!$A$2:$B$13,2,FALSE),""),"") -> d Mi | E18: =IF(MONTH(DATE($G$1,5,15))=5,TEXT(DATE($G$1,5,15),"d")&" "&CHOOSE(WEEKDAY(DATE($G$1,5,15),2),"Mo","Di","Mi","Do","Fr","Sa","So")&IFERROR(CHAR(10)&VLOOKUP(DATE($G$1,5,15),Feiertage!$A$2:$B$13,2,FALSE),""),"") -> d Fr | F18: =IF(MONTH(DATE($G$1,6,15))=6,TEXT(DATE($G$1,6,15),"d")&" "&CHOOSE(WEEKDAY(DATE($G$1,6,15),2),"Mo","Di","Mi","Do","Fr","Sa","So")&IFERROR(CHAR(10)&VLOOKUP(DATE($G$1,6,15),Feiertage!$A$2:$B$13,2,FALSE),""),"") -> d Mo
A19: =IF(MONTH(DATE($G$1,1,16))=1,TEXT(DATE($G$1,1,16),"d")&" "&CHOOSE(WEEKDAY(DATE($G$1,1,16),2),"Mo","Di","Mi","Do","Fr","Sa","So")&IFERROR(CHAR(10)&VLOOKUP(DATE($G$1,1,16),Feiertage!$A$2:$B$13,2,FALSE),""),"") -> d Fr | B19: =IF(MONTH(DATE($G$1,2,16))=2,TEXT(DATE($G$1,2,16),"d")&" "&CHOOSE(WEEKDAY(DATE($G$1,2,16),2),"Mo","Di","Mi","Do","Fr","Sa","So")&IFERROR(CHAR(10)&VLOOKUP(DATE($G$1,2,16),Feiertage!$A$2:$B$13,2,FALSE),""),"") -> d Mo | C19: =IF(MONTH(DATE($G$1,3,16))=3,TEXT(DATE($G$1,3,16),"d")&" "&CHOOSE(WEEKDAY(DATE($G$1,3,16),2),"Mo","Di","Mi","Do","Fr","Sa","So")&IFERROR(CHAR(10)&VLOOKUP(DATE($G$1,3,16),Feiertage!$A$2:$B$13,2,FALSE),""),"") -> d Mo | D19: =IF(MONTH(DATE($G$1,4,16))=4,TEXT(DATE($G$1,4,16),"d")&" "&CHOOSE(WEEKDAY(DATE($G$1,4,16),2),"Mo","Di","Mi","Do","Fr","Sa","So")&IFERROR(CHAR(10)&VLOOKUP(DATE($G$1,4,16),Feiertage!$A$2:$B$13,2,FALSE),""),"") -> d Do | E19: =IF(MONTH(DATE($G$1,5,16))=5,TEXT(DATE($G$1,5,16),"d")&" "&CHOOSE(WEEKDAY(DATE($G$1,5,16),2),"Mo","Di","Mi","Do","Fr","Sa","So")&IFERROR(CHAR(10)&VLOOKUP(DATE($G$1,5,16),Feiertage!$A$2:$B$13,2,FALSE),""),"") -> d Sa | F19: =IF(MONTH(DATE($G$1,6,16))=6,TEXT(DATE($G$1,6,16),"d")&" "&CHOOSE(WEEKDAY(DATE($G$1,6,16),2),"Mo","Di","Mi","Do","Fr","Sa","So")&IFERROR(CHAR(10)&VLOOKUP(DATE($G$1,6,16),Feiertage!$A$2:$B$13,2,FALSE),""),"") -> d Di
A20: =IF(MONTH(DATE($G$1,1,17))=1,TEXT(DATE($G$1,1,17),"d")&" "&CHOOSE(WEEKDAY(DATE($G$1,1,17),2),"Mo","Di","Mi","Do","Fr","Sa","So")&IFERROR(CHAR(10)&VLOOKUP(DATE($G$1,1,17),Feiertage!$A$2:$B$13,2,FALSE),""),"") -> d Sa | B20: =IF(MONTH(DATE($G$1,2,17))=2,TEXT(DATE($G$1,2,17),"d")&" "&CHOOSE(WEEKDAY(DATE($G$1,2,17),2),"Mo","Di","Mi","Do","Fr","Sa","So")&IFERROR(CHAR(10)&VLOOKUP(DATE($G$1,2,17),Feiertage!$A$2:$B$13,2,FALSE),""),"") -> d Di | C20: =IF(MONTH(DATE($G$1,3,17))=3,TEXT(DATE($G$1,3,17),"d")&" "&CHOOSE(WEEKDAY(DATE($G$1,3,17),2),"Mo","Di","Mi","Do","Fr","Sa","So")&IFERROR(CHAR(10)&VLOOKUP(DATE($G$1,3,17),Feiertage!$A$2:$B$13,2,FALSE),""),"") -> d Di | D20: =IF(MONTH(DATE($G$1,4,17))=4,TEXT(DATE($G$1,4,17),"d")&" "&CHOOSE(WEEKDAY(DATE($G$1,4,17),2),"Mo","Di","Mi","Do","Fr","Sa","So")&IFERROR(CHAR(10)&VLOOKUP(DATE($G$1,4,17),Feiertage!$A$2:$B$13,2,FALSE),""),"") -> d Fr | E20: =IF(MONTH(DATE($G$1,5,17))=5,TEXT(DATE($G$1,5,17),"d")&" "&CHOOSE(WEEKDAY(DATE($G$1,5,17),2),"Mo","Di","Mi","Do","Fr","Sa","So")&IFERROR(CHAR(10)&VLOOKUP(DATE($G$1,5,17),Feiertage!$A$2:$B$13,2,FALSE),""),"") -> d So | F20: =IF(MONTH(DATE($G$1,6,17))=6,TEXT(DATE($G$1,6,17),"d")&" "&CHOOSE(WEEKDAY(DATE($G$1,6,17),2),"Mo","Di","Mi","Do","Fr","Sa","So")&IFERROR(CHAR(10)&VLOOKUP(DATE($G$1,6,17),Feiertage!$A$2:$B$13,2,FALSE),""),"") -> d Mi
A21: =IF(MONTH(DATE($G$1,1,18))=1,TEXT(DATE($G$1,1,18),"d")&" "&CHOOSE(WEEKDAY(DATE($G$1,1,18),2),"Mo","Di","Mi","Do","Fr","Sa","So")&IFERROR(CHAR(10)&VLOOKUP(DATE($G$1,1,18),Feiertage!$A$2:$B$13,2,FALSE),""),"") -> d So | B21: =IF(MONTH(DATE($G$1,2,18))=2,TEXT(DATE($G$1,2,18),"d")&" "&CHOOSE(WEEKDAY(DATE($G$1,2,18),2),"Mo","Di","Mi","Do","Fr","Sa","So")&IFERROR(CHAR(10)&VLOOKUP(DATE($G$1,2,18),Feiertage!$A$2:$B$13,2,FALSE),""),"") -> d Mi | C21: =IF(MONTH(DATE($G$1,3,18))=3,TEXT(DATE($G$1,3,18),"d")&" "&CHOOSE(WEEKDAY(DATE($G$1,3,18),2),"Mo","Di","Mi","Do","Fr","Sa","So")&IFERROR(CHAR(10)&VLOOKUP(DATE($G$1,3,18),Feiertage!$A$2:$B$13,2,FALSE),""),"") -> d Mi | D21: =IF(MONTH(DATE($G$1,4,18))=4,TEXT(DATE($G$1,4,18),"d")&" "&CHOOSE(WEEKDAY(DATE($G$1,4,18),2),"Mo","Di","Mi","Do","Fr","Sa","So")&IFERROR(CHAR(10)&VLOOKUP(DATE($G$1,4,18),Feiertage!$A$2:$B$13,2,FALSE),""),"") -> d Sa | E21: =IF(MONTH(DATE($G$1,5,18))=5,TEXT(DATE($G$1,5,18),"d")&" "&CHOOSE(WEEKDAY(DATE($G$1,5,18),2),"Mo","Di","Mi","Do","Fr","Sa","So")&IFERROR(CHAR(10)&VLOOKUP(DATE($G$1,5,18),Feiertage!$A$2:$B$13,2,FALSE),""),"") -> d Mo | F21: =IF(MONTH(DATE($G$1,6,18))=6,TEXT(DATE($G$1,6,18),"d")&" "&CHOOSE(WEEKDAY(DATE($G$1,6,18),2),"Mo","Di","Mi","Do","Fr","Sa","So")&IFERROR(CHAR(10)&VLOOKUP(DATE($G$1,6,18),Feiertage!$A$2:$B$13,2,FALSE),""),"") -> d Do
A22: =IF(MONTH(DATE($G$1,1,19))=1,TEXT(DATE($G$1,1,19),"d")&" "&CHOOSE(WEEKDAY(DATE($G$1,1,19),2),"Mo","Di","Mi","Do","Fr","Sa","So")&IFERROR(CHAR(10)&VLOOKUP(DATE($G$1,1,19),Feiertage!$A$2:$B$13,2,FALSE),""),"") -> d Mo | B22: =IF(MONTH(DATE($G$1,2,19))=2,TEXT(DATE($G$1,2,19),"d")&" "&CHOOSE(WEEKDAY(DATE($G$1,2,19),2),"Mo","Di","Mi","Do","Fr","Sa","So")&IFERROR(CHAR(10)&VLOOKUP(DATE($G$1,2,19),Feiertage!$A$2:$B$13,2,FALSE),""),"") -> d Do | C22: =IF(MONTH(DATE($G$1,3,19))=3,TEXT(DATE($G$1,3,19),"d")&" "&CHOOSE(WEEKDAY(DATE($G$1,3,19),2),"Mo","Di","Mi","Do","Fr","Sa","So")&IFERROR(CHAR(10)&VLOOKUP(DATE($G$1,3,19),Feiertage!$A$2:$B$13,2,FALSE),""),"") -> d Do | D22: =IF(MONTH(DATE($G$1,4,19))=4,TEXT(DATE($G$1,4,19),"d")&" "&CHOOSE(WEEKDAY(DATE($G$1,4,19),2),"Mo","Di","Mi","Do","Fr","Sa","So")&IFERROR(CHAR(10)&VLOOKUP(DATE($G$1,4,19),Feiertage!$A$2:$B$13,2,FALSE),""),"") -> d So | E22: =IF(MONTH(DATE($G$1,5,19))=5,TEXT(DATE($G$1,5,19),"d")&" "&CHOOSE(WEEKDAY(DATE($G$1,5,19),2),"Mo","Di","Mi","Do","Fr","Sa","So")&IFERROR(CHAR(10)&VLOOKUP(DATE($G$1,5,19),Feiertage!$A$2:$B$13,2,FALSE),""),"") -> d Di | F22: =IF(MONTH(DATE($G$1,6,19))=6,TEXT(DATE($G$1,6,19),"d")&" "&CHOOSE(WEEKDAY(DATE($G$1,6,19),2),"Mo","Di","Mi","Do","Fr","Sa","So")&IFERROR(CHAR(10)&VLOOKUP(DATE($G$1,6,19),Feiertage!$A$2:$B$13,2,FALSE),""),"") -> d Fr
A23: =IF(MONTH(DATE($G$1,1,20))=1,TEXT(DATE($G$1,1,20),"d")&" "&CHOOSE(WEEKDAY(DATE($G$1,1,20),2),"Mo","Di","Mi","Do","Fr","Sa","So")&IFERROR(CHAR(10)&VLOOKUP(DATE($G$1,1,20),Feiertage!$A$2:$B$13,2,FALSE),""),"") -> d Di | B23: =IF(MONTH(DATE($G$1,2,20))=2,TEXT(DATE($G$1,2,20),"d")&" "&CHOOSE(WEEKDAY(DATE($G$1,2,20),2),"Mo","Di","Mi","Do","Fr","Sa","So")&IFERROR(CHAR(10)&VLOOKUP(DATE($G$1,2,20),Feiertage!$A$2:$B$13,2,FALSE),""),"") -> d Fr | C23: =IF(MONTH(DATE($G$1,3,20))=3,TEXT(DATE($G$1,3,20),"d")&" "&CHOOSE(WEEKDAY(DATE($G$1,3,20),2),"Mo","Di","Mi","Do","Fr","Sa","So")&IFERROR(CHAR(10)&VLOOKUP(DATE($G$1,3,20),Feiertage!$A$2:$B$13,2,FALSE),""),"") -> d Fr | D23: =IF(MONTH(DATE($G$1,4,20))=4,TEXT(DATE($G$1,4,20),"d")&" "&CHOOSE(WEEKDAY(DATE($G$1,4,20),2),"Mo","Di","Mi","Do","Fr","Sa","So")&IFERROR(CHAR(10)&VLOOKUP(DATE($G$1,4,20),Feiertage!$A$2:$B$13,2,FALSE),""),"") -> d Mo | E23: =IF(MONTH(DATE($G$1,5,20))=5,TEXT(DATE($G$1,5,20),"d")&" "&CHOOSE(WEEKDAY(DATE($G$1,5,20),2),"Mo","Di","Mi","Do","Fr","Sa","So")&IFERROR(CHAR(10)&VLOOKUP(DATE($G$1,5,20),Feiertage!$A$2:$B$13,2,FALSE),""),"") -> d Mi | F23: =IF(MONTH(DATE($G$1,6,20))=6,TEXT(DATE($G$1,6,20),"d")&" "&CHOOSE(WEEKDAY(DATE($G$1,6,20),2),"Mo","Di","Mi","Do","Fr","Sa","So")&IFERROR(CHAR(10)&VLOOKUP(DATE($G$1,6,20),Feiertage!$A$2:$B$13,2,FALSE),""),"") -> d Sa
A24: =IF(MONTH(DATE($G$1,1,21))=1,TEXT(DATE($G$1,1,21),"d")&" "&CHOOSE(WEEKDAY(DATE($G$1,1,21),2),"Mo","Di","Mi","Do","Fr","Sa","So")&IFERROR(CHAR(10)&VLOOKUP(DATE($G$1,1,21),Feiertage!$A$2:$B$13,2,FALSE),""),"") -> d Mi | B24: =IF(MONTH(DATE($G$1,2,21))=2,TEXT(DATE($G$1,2,21),"d")&" "&CHOOSE(WEEKDAY(DATE($G$1,2,21),2),"Mo","Di","Mi","Do","Fr","Sa","So")&IFERROR(CHAR(10)&VLOOKUP(DATE($G$1,2,21),Feiertage!$A$2:$B$13,2,FALSE),""),"") -> d Sa | C24: =IF(MONTH(DATE($G$1,3,21))=3,TEXT(DATE($G$1,3,21),"d")&" "&CHOOSE(WEEKDAY(DATE($G$1,3,21),2),"Mo","Di","Mi","Do","Fr","Sa","So")&IFERROR(CHAR(10)&VLOOKUP(DATE($G$1,3,21),Feiertage!$A$2:$B$13,2,FALSE),""),"") -> d Sa | D24: =IF(MONTH(DATE($G$1,4,21))=4,TEXT(DATE($G$1,4,21),"d")&" "&CHOOSE(WEEKDAY(DATE($G$1,4,21),2),"Mo","Di","Mi","Do","Fr","Sa","So")&IFERROR(CHAR(10)&VLOOKUP(DATE($G$1,4,21),Feiertage!$A$2:$B$13,2,FALSE),""),"") -> d Di | E24: =IF(MONTH(DATE($G$1,5,21))=5,TEXT(DATE($G$1,5,21),"d")&" "&CHOOSE(WEEKDAY(DATE($G$1,5,21),2),"Mo","Di","Mi","Do","Fr","Sa","So")&IFERROR(CHAR(10)&VLOOKUP(DATE($G$1,5,21),Feiertage!$A$2:$B$13,2,FALSE),""),"") -> d Do | F24: =IF(MONTH(DATE($G$1,6,21))=6,TEXT(DATE($G$1,6,21),"d")&" "&CHOOSE(WEEKDAY(DATE($G$1,6,21),2),"Mo","Di","Mi","Do","Fr","Sa","So")&IFERROR(CHAR(10)&VLOOKUP(DATE($G$1,6,21),Feiertage!$A$2:$B$13,2,FALSE),""),"") -> d So
A25: =IF(MONTH(DATE($G$1,1,22))=1,TEXT(DATE($G$1,1,22),"d")&" "&CHOOSE(WEEKDAY(DATE($G$1,1,22),2),"Mo","Di","Mi","Do","Fr","Sa","So")&IFERROR(CHAR(10)&VLOOKUP(DATE($G$1,1,22),Feiertage!$A$2:$B$13,2,FALSE),""),"") -> d Do | B25: =IF(MONTH(DATE($G$1,2,22))=2,TEXT(DATE($G$1,2,22),"d")&" "&CHOOSE(WEEKDAY(DATE($G$1,2,22),2),"Mo","Di","Mi","Do","Fr","Sa","So")&IFERROR(CHAR(10)&VLOOKUP(DATE($G$1,2,22),Feiertage!$A$2:$B$13,2,FALSE),""),"") -> d So | C25: =IF(MONTH(DATE($G$1,3,22))=3,TEXT(DATE($G$1,3,22),"d")&" "&CHOOSE(WEEKDAY(DATE($G$1,3,22),2),"Mo","Di","Mi","Do","Fr","Sa","So")&IFERROR(CHAR(10)&VLOOKUP(DATE($G$1,3,22),Feiertage!$A$2:$B$13,2,FALSE),""),"") -> d So | D25: =IF(MONTH(DATE($G$1,4,22))=4,TEXT(DATE($G$1,4,22),"d")&" "&CHOOSE(WEEKDAY(DATE($G$1,4,22),2),"Mo","Di","Mi","Do","Fr","Sa","So")&IFERROR(CHAR(10)&VLOOKUP(DATE($G$1,4,22),Feiertage!$A$2:$B$13,2,FALSE),""),"") -> d Mi | E25: =IF(MONTH(DATE($G$1,5,22))=5,TEXT(DATE($G$1,5,22),"d")&" "&CHOOSE(WEEKDAY(DATE($G$1,5,22),2),"Mo","Di","Mi","Do","Fr","Sa","So")&IFERROR(CHAR(10)&VLOOKUP(DATE($G$1,5,22),Feiertage!$A$2:$B$13,2,FALSE),""),"") -> d Fr | F25: =IF(MONTH(DATE($G$1,6,22))=6,TEXT(DATE($G$1,6,22),"d")&" "&CHOOSE(WEEKDAY(DATE($G$1,6,22),2),"Mo","Di","Mi","Do","Fr","Sa","So")&IFERROR(CHAR(10)&VLOOKUP(DATE($G$1,6,22),Feiertage!$A$2:$B$13,2,FALSE),""),"") -> d Mo
A26: =IF(MONTH(DATE($G$1,1,23))=1,TEXT(DATE($G$1,1,23),"d")&" "&CHOOSE(WEEKDAY(DATE($G$1,1,23),2),"Mo","Di","Mi","Do","Fr","Sa","So")&IFERROR(CHAR(10)&VLOOKUP(DATE($G$1,1,23),Feiertage!$A$2:$B$13,2,FALSE),""),"") -> d Fr | B26: =IF(MONTH(DATE($G$1,2,23))=2,TEXT(DATE($G$1,2,23),"d")&" "&CHOOSE(WEEKDAY(DATE($G$1,2,23),2),"Mo","Di","Mi","Do","Fr","Sa","So")&IFERROR(CHAR(10)&VLOOKUP(DATE($G$1,2,23),Feiertage!$A$2:$B$13,2,FALSE),""),"") -> d Mo | C26: =IF(MONTH(DATE($G$1,3,23))=3,TEXT(DATE($G$1,3,23),"d")&" "&CHOOSE(WEEKDAY(DATE($G$1,3,23),2),"Mo","Di","Mi","Do","Fr","Sa","So")&IFERROR(CHAR(10)&VLOOKUP(DATE($G$1,3,23),Feiertage!$A$2:$B$13,2,FALSE),""),"") -> d Mo | D26: =IF(MONTH(DATE($G$1,4,23))=4,TEXT(DATE($G$1,4,23),"d")&" "&CHOOSE(WEEKDAY(DATE($G$1,4,23),2),"Mo","Di","Mi","Do","Fr","Sa","So")&IFERROR(CHAR(10)&VLOOKUP(DATE($G$1,4,23),Feiertage!$A$2:$B$13,2,FALSE),""),"") -> d Do | E26: =IF(MONTH(DATE($G$1,5,23))=5,TEXT(DATE($G$1,5,23),"d")&" "&CHOOSE(WEEKDAY(DATE($G$1,5,23),2),"Mo","Di","Mi","Do","Fr","Sa","So")&IFERROR(CHAR(10)&VLOOKUP(DATE($G$1,5,23),Feiertage!$A$2:$B$13,2,FALSE),""),"") -> d Sa | F26: =IF(MONTH(DATE($G$1,6,23))=6,TEXT(DATE($G$1,6,23),"d")&" "&CHOOSE(WEEKDAY(DATE($G$1,6,23),2),"Mo","Di","Mi","Do","Fr","Sa","So")&IFERROR(CHAR(10)&VLOOKUP(DATE($G$1,6,23),Feiertage!$A$2:$B$13,2,FALSE),""),"") -> d Di
A27: =IF(MONTH(DATE($G$1,1,24))=1,TEXT(DATE($G$1,1,24),"d")&" "&CHOOSE(WEEKDAY(DATE($G$1,1,24),2),"Mo","Di","Mi","Do","Fr","Sa","So")&IFERROR(CHAR(10)&VLOOKUP(DATE($G$1,1,24),Feiertage!$A$2:$B$13,2,FALSE),""),"") -> d Sa | B27: =IF(MONTH(DATE($G$1,2,24))=2,TEXT(DATE($G$1,2,24),"d")&" "&CHOOSE(WEEKDAY(DATE($G$1,2,24),2),"Mo","Di","Mi","Do","Fr","Sa","So")&IFERROR(CHAR(10)&VLOOKUP(DATE($G$1,2,24),Feiertage!$A$2:$B$13,2,FALSE),""),"") -> d Di | C27: =IF(MONTH(DATE($G$1,3,24))=3,TEXT(DATE($G$1,3,24),"d")&" "&CHOOSE(WEEKDAY(DATE($G$1,3,24),2),"Mo","Di","Mi","Do","Fr","Sa","So")&IFERROR(CHAR(10)&VLOOKUP(DATE($G$1,3,24),Feiertage!$A$2:$B$13,2,FALSE),""),"") -> d Di | D27: =IF(MONTH(DATE($G$1,4,24))=4,TEXT(DATE($G$1,4,24),"d")&" "&CHOOSE(WEEKDAY(DATE($G$1,4,24),2),"Mo","Di","Mi","Do","Fr","Sa","So")&IFERROR(CHAR(10)&VLOOKUP(DATE($G$1,4,24),Feiertage!$A$2:$B$13,2,FALSE),""),"") -> d Fr | E27: =IF(MONTH(DATE($G$1,5,24))=5,TEXT(DATE($G$1,5,24),"d")&" "&CHOOSE(WEEKDAY(DATE($G$1,5,24),2),"Mo","Di","Mi","Do","Fr","Sa","So")&IFERROR(CHAR(10)&VLOOKUP(DATE($G$1,5,24),Feiertage!$A$2:$B$13,2,FALSE),""),"") -> d So Pfingsten | F27: =IF(MONTH(DATE($G$1,6,24))=6,TEXT(DATE($G$1,6,24),"d")&" "&CHOOSE(WEEKDAY(DATE($G$1,6,24),2),"Mo","Di","Mi","Do","Fr","Sa","So")&IFERROR(CHAR(10)&VLOOKUP(DATE($G$1,6,24),Feiertage!$A$2:$B$13,2,FALSE),""),"") -> d Mi
A28: =IF(MONTH(DATE($G$1,1,25))=1,TEXT(DATE($G$1,1,25),"d")&" "&CHOOSE(WEEKDAY(DATE($G$1,1,25),2),"Mo","Di","Mi","Do","Fr","Sa","So")&IFERROR(CHAR(10)&VLOOKUP(DATE($G$1,1,25),Feiertage!$A$2:$B$13,2,FALSE),""),"") -> d So | B28: =IF(MONTH(DATE($G$1,2,25))=2,TEXT(DATE($G$1,2,25),"d")&" "&CHOOSE(WEEKDAY(DATE($G$1,2,25),2),"Mo","Di","Mi","Do","Fr","Sa","So")&IFERROR(CHAR(10)&VLOOKUP(DATE($G$1,2,25),Feiertage!$A$2:$B$13,2,FALSE),""),"") -> d Mi | C28: =IF(MONTH(DATE($G$1,3,25))=3,TEXT(DATE($G$1,3,25),"d")&" "&CHOOSE(WEEKDAY(DATE($G$1,3,25),2),"Mo","Di","Mi","Do","Fr","Sa","So")&IFERROR(CHAR(10)&VLOOKUP(DATE($G$1,3,25),Feiertage!$A$2:$B$13,2,FALSE),""),"") -> d Mi | D28: =IF(MONTH(DATE($G$1,4,25))=4,TEXT(DATE($G$1,4,25),"d")&" "&CHOOSE(WEEKDAY(DATE($G$1,4,25),2),"Mo","Di","Mi","Do","Fr","Sa","So")&IFERROR(CHAR(10)&VLOOKUP(DATE($G$1,4,25),Feiertage!$A$2:$B$13,2,FALSE),""),"") -> d Sa | E28: =IF(MONTH(DATE($G$1,5,25))=5,TEXT(DATE($G$1,5,25),"d")&" "&CHOOSE(WEEKDAY(DATE($G$1,5,25),2),"Mo","Di","Mi","Do","Fr","Sa","So")&IFERROR(CHAR(10)&VLOOKUP(DATE($G$1,5,25),Feiertage!$A$2:$B$13,2,FALSE),""),"") -> d Mo Pfingstmontag | F28: =IF(MONTH(DATE($G$1,6,25))=6,TEXT(DATE($G$1,6,25),"d")&" "&CHOOSE(WEEKDAY(DATE($G$1,6,25),2),"Mo","Di","Mi","Do","Fr","Sa","So")&IFERROR(CHAR(10)&VLOOKUP(DATE($G$1,6,25),Feiertage!$A$2:$B$13,2,FALSE),""),"") -> d Do
A29: =IF(MONTH(DATE($G$1,1,26))=1,TEXT(DATE($G$1,1,26),"d")&" "&CHOOSE(WEEKDAY(DATE($G$1,1,26),2),"Mo","Di","Mi","Do","Fr","Sa","So")&IFERROR(CHAR(10)&VLOOKUP(DATE($G$1,1,26),Feiertage!$A$2:$B$13,2,FALSE),""),"") -> d Mo | B29: =IF(MONTH(DATE($G$1,2,26))=2,TEXT(DATE($G$1,2,26),"d")&" "&CHOOSE(WEEKDAY(DATE($G$1,2,26),2),"Mo","Di","Mi","Do","Fr","Sa","So")&IFERROR(CHAR(10)&VLOOKUP(DATE($G$1,2,26),Feiertage!$A$2:$B$13,2,FALSE),""),"") -> d Do | C29: =IF(MONTH(DATE($G$1,3,26))=3,TEXT(DATE($G$1,3,26),"d")&" "&CHOOSE(WEEKDAY(DATE($G$1,3,26),2),"Mo","Di","Mi","Do","Fr","Sa","So")&IFERROR(CHAR(10)&VLOOKUP(DATE($G$1,3,26),Feiertage!$A$2:$B$13,2,FALSE),""),"") -> d Do | D29: =IF(MONTH(DATE($G$1,4,26))=4,TEXT(DATE($G$1,4,26),"d")&" "&CHOOSE(WEEKDAY(DATE($G$1,4,26),2),"Mo","Di","Mi","Do","Fr","Sa","So")&IFERROR(CHAR(10)&VLOOKUP(DATE($G$1,4,26),Feiertage!$A$2:$B$13,2,FALSE),""),"") -> d So | E29: =IF(MONTH(DATE($G$1,5,26))=5,TEXT(DATE($G$1,5,26),"d")&" "&CHOOSE(WEEKDAY(DATE($G$1,5,26),2),"Mo","Di","Mi","Do","Fr","Sa","So")&IFERROR(CHAR(10)&VLOOKUP(DATE($G$1,5,26),Feiertage!$A$2:$B$13,2,FALSE),""),"") -> d Di | F29: =IF(MONTH(DATE($G$1,6,26))=6,TEXT(DATE($G$1,6,26),"d")&" "&CHOOSE(WEEKDAY(DATE($G$1,6,26),2),"Mo","Di","Mi","Do","Fr","Sa","So")&IFERROR(CHAR(10)&VLOOKUP(DATE($G$1,6,26),Feiertage!$A$2:$B$13,2,FALSE),""),"") -> d Fr
A30: =IF(MONTH(DATE($G$1,1,27))=1,TEXT(DATE($G$1,1,27),"d")&" "&CHOOSE(WEEKDAY(DATE($G$1,1,27),2),"Mo","Di","Mi","Do","Fr","Sa","So")&IFERROR(CHAR(10)&VLOOKUP(DATE($G$1,1,27),Feiertage!$A$2:$B$13,2,FALSE),""),"") -> d Di | B30: =IF(MONTH(DATE($G$1,2,27))=2,TEXT(DATE($G$1,2,27),"d")&" "&CHOOSE(WEEKDAY(DATE($G$1,2,27),2),"Mo","Di","Mi","Do","Fr","Sa","So")&IFERROR(CHAR(10)&VLOOKUP(DATE($G$1,2,27),Feiertage!$A$2:$B$13,2,FALSE),""),"") -> d Fr | C30: =IF(MONTH(DATE($G$1,3,27))=3,TEXT(DATE($G$1,3,27),"d")&" "&CHOOSE(WEEKDAY(DATE($G$1,3,27),2),"Mo","Di","Mi","Do","Fr","Sa","So")&IFERROR(CHAR(10)&VLOOKUP(DATE($G$1,3,27),Feiertage!$A$2:$B$13,2,FALSE),""),"") -> d Fr | D30: =IF(MONTH(DATE($G$1,4,27))=4,TEXT(DATE($G$1,4,27),"d")&" "&CHOOSE(WEEKDAY(DATE($G$1,4,27),2),"Mo","Di","Mi","Do","Fr","Sa","So")&IFERROR(CHAR(10)&VLOOKUP(DATE($G$1,4,27),Feiertage!$A$2:$B$13,2,FALSE),""),"") -> d Mo | E30: =IF(MONTH(DATE($G$1,5,27))=5,TEXT(DATE($G$1,5,27),"d")&" "&CHOOSE(WEEKDAY(DATE($G$1,5,27),2),"Mo","Di","Mi","Do","Fr","Sa","So")&IFERROR(CHAR(10)&VLOOKUP(DATE($G$1,5,27),Feiertage!$A$2:$B$13,2,FALSE),""),"") -> d Mi | F30: =IF(MONTH(DATE($G$1,6,27))=6,TEXT(DATE($G$1,6,27),"d")&" "&CHOOSE(WEEKDAY(DATE($G$1,6,27),2),"Mo","Di","Mi","Do","Fr","Sa","So")&IFERROR(CHAR(10)&VLOOKUP(DATE($G$1,6,27),Feiertage!$A$2:$B$13,2,FALSE),""),"") -> d Sa
A31: =IF(MONTH(DATE($G$1,1,28))=1,TEXT(DATE($G$1,1,28),"d")&" "&CHOOSE(WEEKDAY(DATE($G$1,1,28),2),"Mo","Di","Mi","Do","Fr","Sa","So")&IFERROR(CHAR(10)&VLOOKUP(DATE($G$1,1,28),Feiertage!$A$2:$B$13,2,FALSE),""),"") -> d Mi | B31: =IF(MONTH(DATE($G$1,2,28))=2,TEXT(DATE($G$1,2,28),"d")&" "&CHOOSE(WEEKDAY(DATE($G$1,2,28),2),"Mo","Di","Mi","Do","Fr","Sa","So")&IFERROR(CHAR(10)&VLOOKUP(DATE($G$1,2,28),Feiertage!$A$2:$B$13,2,FALSE),""),"") -> d Sa | C31: =IF(MONTH(DATE($G$1,3,28))=3,TEXT(DATE($G$1,3,28),"d")&" "&CHOOSE(WEEKDAY(DATE($G$1,3,28),2),"Mo","Di","Mi","Do","Fr","Sa","So")&IFERROR(CHAR(10)&VLOOKUP(DATE($G$1,3,28),Feiertage!$A$2:$B$13,2,FALSE),""),"") -> d Sa | D31: =IF(MONTH(DATE($G$1,4,28))=4,TEXT(DATE($G$1,4,28),"d")&" "&CHOOSE(WEEKDAY(DATE($G$1,4,28),2),"Mo","Di","Mi","Do","Fr","Sa","So")&IFERROR(CHAR(10)&VLOOKUP(DATE($G$1,4,28),Feiertage!$A$2:$B$13,2,FALSE),""),"") -> d Di | E31: =IF(MONTH(DATE($G$1,5,28))=5,TEXT(DATE($G$1,5,28),"d")&" "&CHOOSE(WEEKDAY(DATE($G$1,5,28),2),"Mo","Di","Mi","Do","Fr","Sa","So")&IFERROR(CHAR(10)&VLOOKUP(DATE($G$1,5,28),Feiertage!$A$2:$B$13,2,FALSE),""),"") -> d Do | F31: =IF(MONTH(DATE($G$1,6,28))=6,TEXT(DATE($G$1,6,28),"d")&" "&CHOOSE(WEEKDAY(DATE($G$1,6,28),2),"Mo","Di","Mi","Do","Fr","Sa","So")&IFERROR(CHAR(10)&VLOOKUP(DATE($G$1,6,28),Feiertage!$A$2:$B$13,2,FALSE),""),"") -> d So
A32: =IF(MONTH(DATE($G$1,1,29))=1,TEXT(DATE($G$1,1,29),"d")&" "&CHOOSE(WEEKDAY(DATE($G$1,1,29),2),"Mo","Di","Mi","Do","Fr","Sa","So")&IFERROR(CHAR(10)&VLOOKUP(DATE($G$1,1,29),Feiertage!$A$2:$B$13,2,FALSE),""),"") -> d Do | B32: =IF(MONTH(DATE($G$1,2,29))=2,TEXT(DATE($G$1,2,29),"d")&" "&CHOOSE(WEEKDAY(DATE($G$1,2,29),2),"Mo","Di","Mi","Do","Fr","Sa","So")&IFERROR(CHAR(10)&VLOOKUP(DATE($G$1,2,29),Feiertage!$A$2:$B$13,2,FALSE),""),"") | C32: =IF(MONTH(DATE($G$1,3,29))=3,TEXT(DATE($G$1,3,29),"d")&" "&CHOOSE(WEEKDAY(DATE($G$1,3,29),2),"Mo","Di","Mi","Do","Fr","Sa","So")&IFERROR(CHAR(10)&VLOOKUP(DATE($G$1,3,29),Feiertage!$A$2:$B$13,2,FALSE),""),"") -> d So | D32: =IF(MONTH(DATE($G$1,4,29))=4,TEXT(DATE($G$1,4,29),"d")&" "&CHOOSE(WEEKDAY(DATE($G$1,4,29),2),"Mo","Di","Mi","Do","Fr","Sa","So")&IFERROR(CHAR(10)&VLOOKUP(DATE($G$1,4,29),Feiertage!$A$2:$B$13,2,FALSE),""),"") -> d Mi | E32: =IF(MONTH(DATE($G$1,5,29))=5,TEXT(DATE($G$1,5,29),"d")&" "&CHOOSE(WEEKDAY(DATE($G$1,5,29),2),"Mo","Di","Mi","Do","Fr","Sa","So")&IFERROR(CHAR(10)&VLOOKUP(DATE($G$1,5,29),Feiertage!$A$2:$B$13,2,FALSE),""),"") -> d Fr | F32: =IF(MONTH(DATE($G$1,6,29))=6,TEXT(DATE($G$1,6,29),"d")&" "&CHOOSE(WEEKDAY(DATE($G$1,6,29),2),"Mo","Di","Mi","Do","Fr","Sa","So")&IFERROR(CHAR(10)&VLOOKUP(DATE($G$1,6,29),Feiertage!$A$2:$B$13,2,FALSE),""),"") -> d Mo
A33: =IF(MONTH(DATE($G$1,1,30))=1,TEXT(DATE($G$1,1,30),"d")&" "&CHOOSE(WEEKDAY(DATE($G$1,1,30),2),"Mo","Di","Mi","Do","Fr","Sa","So")&IFERROR(CHAR(10)&VLOOKUP(DATE($G$1,1,30),Feiertage!$A$2:$B$13,2,FALSE),""),"") -> d Fr | B33: =IF(MONTH(DATE($G$1,2,30))=2,TEXT(DATE($G$1,2,30),"d")&" "&CHOOSE(WEEKDAY(DATE($G$1,2,30),2),"Mo","Di","Mi","Do","Fr","Sa","So")&IFERROR(CHAR(10)&VLOOKUP(DATE($G$1,2,30),Feiertage!$A$2:$B$13,2,FALSE),""),"") | C33: =IF(MONTH(DATE($G$1,3,30))=3,TEXT(DATE($G$1,3,30),"d")&" "&CHOOSE(WEEKDAY(DATE($G$1,3,30),2),"Mo","Di","Mi","Do","Fr","Sa","So")&IFERROR(CHAR(10)&VLOOKUP(DATE($G$1,3,30),Feiertage!$A$2:$B$13,2,FALSE),""),"") -> d Mo | D33: =IF(MONTH(DATE($G$1,4,30))=4,TEXT(DATE($G$1,4,30),"d")&" "&CHOOSE(WEEKDAY(DATE($G$1,4,30),2),"Mo","Di","Mi","Do","Fr","Sa","So")&IFERROR(CHAR(10)&VLOOKUP(DATE($G$1,4,30),Feiertage!$A$2:$B$13,2,FALSE),""),"") -> d Do | E33: =IF(MONTH(DATE($G$1,5,30))=5,TEXT(DATE($G$1,5,30),"d")&" "&CHOOSE(WEEKDAY(DATE($G$1,5,30),2),"Mo","Di","Mi","Do","Fr","Sa","So")&IFERROR(CHAR(10)&VLOOKUP(DATE($G$1,5,30),Feiertage!$A$2:$B$13,2,FALSE),""),"") -> d Sa | F33: =IF(MONTH(DATE($G$1,6,30))=6,TEXT(DATE($G$1,6,30),"d")&" "&CHOOSE(WEEKDAY(DATE($G$1,6,30),2),"Mo","Di","Mi","Do","Fr","Sa","So")&IFERROR(CHAR(10)&VLOOKUP(DATE($G$1,6,30),Feiertage!$A$2:$B$13,2,FALSE),""),"") -> d Di
A34: =IF(MONTH(DATE($G$1,1,31))=1,TEXT(DATE($G$1,1,31),"d")&" "&CHOOSE(WEEKDAY(DATE($G$1,1,31),2),"Mo","Di","Mi","Do","Fr","Sa","So")&IFERROR(CHAR(10)&VLOOKUP(DATE($G$1,1,31),Feiertage!$A$2:$B$13,2,FALSE),""),"") -> d Sa | B34: =IF(MONTH(DATE($G$1,2,31))=2,TEXT(DATE($G$1,2,31),"d")&" "&CHOOSE(WEEKDAY(DATE($G$1,2,31),2),"Mo","Di","Mi","Do","Fr","Sa","So")&IFERROR(CHAR(10)&VLOOKUP(DATE($G$1,2,31),Feiertage!$A$2:$B$13,2,FALSE),""),"") | C34: =IF(MONTH(DATE($G$1,3,31))=3,TEXT(DATE($G$1,3,31),"d")&" "&CHOOSE(WEEKDAY(DATE($G$1,3,31),2),"Mo","Di","Mi","Do","Fr","Sa","So")&IFERROR(CHAR(10)&VLOOKUP(DATE($G$1,3,31),Feiertage!$A$2:$B$13,2,FALSE),""),"") -> d Di | D34: =IF(MONTH(DATE($G$1,4,31))=4,TEXT(DATE($G$1,4,31),"d")&" "&CHOOSE(WEEKDAY(DATE($G$1,4,31),2),"Mo","Di","Mi","Do","Fr","Sa","So")&IFERROR(CHAR(10)&VLOOKUP(DATE($G$1,4,31),Feiertage!$A$2:$B$13,2,FALSE),""),"") | E34: =IF(MONTH(DATE($G$1,5,31))=5,TEXT(DATE($G$1,5,31),"d")&" "&CHOOSE(WEEKDAY(DATE($G$1,5,31),2),"Mo","Di","Mi","Do","Fr","Sa","So")&IFERROR(CHAR(10)&VLOOKUP(DATE($G$1,5,31),Feiertage!$A$2:$B$13,2,FALSE),""),"") -> d So | F34: =IF(MONTH(DATE($G$1,6,31))=6,TEXT(DATE($G$1,6,31),"d")&" "&CHOOSE(WEEKDAY(DATE($G$1,6,31),2),"Mo","Di","Mi","Do","Fr","Sa","So")&IFERROR(CHAR(10)&VLOOKUP(DATE($G$1,6,31),Feiertage!$A$2:$B$13,2,FALSE),""),"")
A40: Juli | B40: August | C40: September | D40: Oktober | E40: November | F40: Dezember
A41: =IF(MONTH(DATE($G$1,7,1))=7,TEXT(DATE($G$1,7,1),"d")&" "&CHOOSE(WEEKDAY(DATE($G$1,7,1),2),"Mo","Di","Mi","Do","Fr","Sa","So")&IFERROR(CHAR(10)&VLOOKUP(DATE($G$1,7,1),Feiertage!$A$2:$B$13,2,FALSE),""),"") -> d Mi | B41: =IF(MONTH(DATE($G$1,8,1))=8,TEXT(DATE($G$1,8,1),"d")&" "&CHOOSE(WEEKDAY(DATE($G$1,8,1),2),"Mo","Di","Mi","Do","Fr","Sa","So")&IFERROR(CHAR(10)&VLOOKUP(DATE($G$1,8,1),Feiertage!$A$2:$B$13,2,FALSE),""),"") -> d Sa | C41: =IF(MONTH(DATE($G$1,9,1))=9,TEXT(DATE($G$1,9,1),"d")&" "&CHOOSE(WEEKDAY(DATE($G$1,9,1),2),"Mo","Di","Mi","Do","Fr","Sa","So")&IFERROR(CHAR(10)&VLOOKUP(DATE($G$1,9,1),Feiertage!$A$2:$B$13,2,FALSE),""),"") -> d Di | D41: =IF(MONTH(DATE($G$1,10,1))=10,TEXT(DATE($G$1,10,1),"d")&" "&CHOOSE(WEEKDAY(DATE($G$1,10,1),2),"Mo","Di","Mi","Do","Fr","Sa","So")&IFERROR(CHAR(10)&VLOOKUP(DATE($G$1,10,1),Feiertage!$A$2:$B$13,2,FALSE),""),"") -> d Do | E41: =IF(MONTH(DATE($G$1,11,1))=11,TEXT(DATE($G$1,11,1),"d")&" "&CHOOSE(WEEKDAY(DATE($G$1,11,1),2),"Mo","Di","Mi","Do","Fr","Sa","So")&IFERROR(CHAR(10)&VLOOKUP(DATE($G$1,11,1),Feiertage!$A$2:$B$13,2,FALSE),""),"") -> d So | F41: =IF(MONTH(DATE($G$1,12,1))=12,TEXT(DATE($G$1,12,1),"d")&" "&CHOOSE(WEEKDAY(DATE($G$1,12,1),2),"Mo","Di","Mi","Do","Fr","Sa","So")&IFERROR(CHAR(10)&VLOOKUP(DATE($G$1,12,1),Feiertage!$A$2:$B$13,2,FALSE),""),"") -> d Di
A42: =IF(MONTH(DATE($G$1,7,2))=7,TEXT(DATE($G$1,7,2),"d")&" "&CHOOSE(WEEKDAY(DATE($G$1,7,2),2),"Mo","Di","Mi","Do","Fr","Sa","So")&IFERROR(CHAR(10)&VLOOKUP(DATE($G$1,7,2),Feiertage!$A$2:$B$13,2,FALSE),""),"") -> d Do | B42: =IF(MONTH(DATE($G$1,8,2))=8,TEXT(DATE($G$1,8,2),"d")&" "&CHOOSE(WEEKDAY(DATE($G$1,8,2),2),"Mo","Di","Mi","Do","Fr","Sa","So")&IFERROR(CHAR(10)&VLOOKUP(DATE($G$1,8,2),Feiertage!$A$2:$B$13,2,FALSE),""),"") -> d So | C42: =IF(MONTH(DATE($G$1,9,2))=9,TEXT(DATE($G$1,9,2),"d")&" "&CHOOSE(WEEKDAY(DATE($G$1,9,2),2),"Mo","Di","Mi","Do","Fr","Sa","So")&IFERROR(CHAR(10)&VLOOKUP(DATE($G$1,9,2),Feiertage!$A$2:$B$13,2,FALSE),""),"") -> d Mi | D42: =IF(MONTH(DATE($G$1,10,2))=10,TEXT(DATE($G$1,10,2),"d")&" "&CHOOSE(WEEKDAY(DATE($G$1,10,2),2),"Mo","Di","Mi","Do","Fr","Sa","So")&IFERROR(CHAR(10)&VLOOKUP(DATE($G$1,10,2),Feiertage!$A$2:$B$13,2,FALSE),""),"") -> d Fr | E42: =IF(MONTH(DATE($G$1,11,2))=11,TEXT(DATE($G$1,11,2),"d")&" "&CHOOSE(WEEKDAY(DATE($G$1,11,2),2),"Mo","Di","Mi","Do","Fr","Sa","So")&IFERROR(CHAR(10)&VLOOKUP(DATE($G$1,11,2),Feiertage!$A$2:$B$13,2,FALSE),""),"") -> d Mo | F42: =IF(MONTH(DATE($G$1,12,2))=12,TEXT(DATE($G$1,12,2),"d")&" "&CHOOSE(WEEKDAY(DATE($G$1,12,2),2),"Mo","Di","Mi","Do","Fr","Sa","So")&IFERROR(CHAR(10)&VLOOKUP(DATE($G$1,12,2),Feiertage!$A$2:$B$13,2,FALSE),""),"") -> d Mi
A43: =IF(MONTH(DATE($G$1,7,3))=7,TEXT(DATE($G$1,7,3),"d")&" "&CHOOSE(WEEKDAY(DATE($G$1,7,3),2),"Mo","Di","Mi","Do","Fr","Sa","So")&IFERROR(CHAR(10)&VLOOKUP(DATE($G$1,7,3),Feiertage!$A$2:$B$13,2,FALSE),""),"") -> d Fr | B43: =IF(MONTH(DATE($G$1,8,3))=8,TEXT(DATE($G$1,8,3),"d")&" "&CHOOSE(WEEKDAY(DATE($G$1,8,3),2),"Mo","Di","Mi","Do","Fr","Sa","So")&IFERROR(CHAR(10)&VLOOKUP(DATE($G$1,8,3),Feiertage!$A$2:$B$13,2,FALSE),""),"") -> d Mo | C43: =IF(MONTH(DATE($G$1,9,3))=9,TEXT(DATE($G$1,9,3),"d")&" "&CHOOSE(WEEKDAY(DATE($G$1,9,3),2),"Mo","Di","Mi","Do","Fr","Sa","So")&IFERROR(CHAR(10)&VLOOKUP(DATE($G$1,9,3),Feiertage!$A$2:$B$13,2,FALSE),""),"") -> d Do | D43: =IF(MONTH(DATE($G$1,10,3))=10,TEXT(DATE($G$1,10,3),"d")&" "&CHOOSE(WEEKDAY(DATE($G$1,10,3),2),"Mo","Di","Mi","Do","Fr","Sa","So")&IFERROR(CHAR(10)&VLOOKUP(DATE($G$1,10,3),Feiertage!$A$2:$B$13,2,FALSE),""),"") -> d Sa Tag der Deutschen Einheit | E43: =IF(MONTH(DATE($G$1,11,3))=11,TEXT(DATE($G$1,11,3),"d")&" "&CHOOSE(WEEKDAY(DATE($G$1,11,3),2),"Mo","Di","Mi","Do","Fr","Sa","So")&IFERROR(CHAR(10)&VLOOKUP(DATE($G$1,11,3),Feiertage!$A$2:$B$13,2,FALSE),""),"") -> d Di | F43: =IF(MONTH(DATE($G$1,12,3))=12,TEXT(DATE($G$1,12,3),"d")&" "&CHOOSE(WEEKDAY(DATE($G$1,12,3),2),"Mo","Di","Mi","Do","Fr","Sa","So")&IFERROR(CHAR(10)&VLOOKUP(DATE($G$1,12,3),Feiertage!$A$2:$B$13,2,FALSE),""),"") -> d Do
A44: =IF(MONTH(DATE($G$1,7,4))=7,TEXT(DATE($G$1,7,4),"d")&" "&CHOOSE(WEEKDAY(DATE($G$1,7,4),2),"Mo","Di","Mi","Do","Fr","Sa","So")&IFERROR(CHAR(10)&VLOOKUP(DATE($G$1,7,4),Feiertage!$A$2:$B$13,2,FALSE),""),"") -> d Sa | B44: =IF(MONTH(DATE($G$1,8,4))=8,TEXT(DATE($G$1,8,4),"d")&" "&CHOOSE(WEEKDAY(DATE($G$1,8,4),2),"Mo","Di","Mi","Do","Fr","Sa","So")&IFERROR(CHAR(10)&VLOOKUP(DATE($G$1,8,4),Feiertage!$A$2:$B$13,2,FALSE),""),"") -> d Di | C44: =IF(MONTH(DATE($G$1,9,4))=9,TEXT(DATE($G$1,9,4),"d")&" "&CHOOSE(WEEKDAY(DATE($G$1,9,4),2),"Mo","Di","Mi","Do","Fr","Sa","So")&IFERROR(CHAR(10)&VLOOKUP(DATE($G$1,9,4),Feiertage!$A$2:$B$13,2,FALSE),""),"") -> d Fr | D44: =IF(MONTH(DATE($G$1,10,4))=10,TEXT(DATE($G$1,10,4),"d")&" "&CHOOSE(WEEKDAY(DATE($G$1,10,4),2),"Mo","Di","Mi","Do","Fr","Sa","So")&IFERROR(CHAR(10)&VLOOKUP(DATE($G$1,10,4),Feiertage!$A$2:$B$13,2,FALSE),""),"") -> d So | E44: =IF(MONTH(DATE($G$1,11,4))=11,TEXT(DATE($G$1,11,4),"d")&" "&CHOOSE(WEEKDAY(DATE($G$1,11,4),2),"Mo","Di","Mi","Do","Fr","Sa","So")&IFERROR(CHAR(10)&VLOOKUP(DATE($G$1,11,4),Feiertage!$A$2:$B$13,2,FALSE),""),"") -> d Mi | F44: =IF(MONTH(DATE($G$1,12,4))=12,TEXT(DATE($G$1,12,4),"d")&" "&CHOOSE(WEEKDAY(DATE($G$1,12,4),2),"Mo","Di","Mi","Do","Fr","Sa","So")&IFERROR(CHAR(10)&VLOOKUP(DATE($G$1,12,4),Feiertage!$A$2:$B$13,2,FALSE),""),"") -> d Fr
A45: =IF(MONTH(DATE($G$1,7,5))=7,TEXT(DATE($G$1,7,5),"d")&" "&CHOOSE(WEEKDAY(DATE($G$1,7,5),2),"Mo","Di","Mi","Do","Fr","Sa","So")&IFERROR(CHAR(10)&VLOOKUP(DATE($G$1,7,5),Feiertage!$A$2:$B$13,2,FALSE),""),"") -> d So | B45: =IF(MONTH(DATE($G$1,8,5))=8,TEXT(DATE($G$1,8,5),"d")&" "&CHOOSE(WEEKDAY(DATE($G$1,8,5),2),"Mo","Di","Mi","Do","Fr","Sa","So")&IFERROR(CHAR(10)&VLOOKUP(DATE($G$1,8,5),Feiertage!$A$2:$B$13,2,FALSE),""),"") -> d Mi | C45: =IF(MONTH(DATE($G$1,9,5))=9,TEXT(DATE($G$1,9,5),"d")&" "&CHOOSE(WEEKDAY(DATE($G$1,9,5),2),"Mo","Di","Mi","Do","Fr","Sa","So")&IFERROR(CHAR(10)&VLOOKUP(DATE($G$1,9,5),Feiertage!$A$2:$B$13,2,FALSE),""),"") -> d Sa | D45: =IF(MONTH(DATE($G$1,10,5))=10,TEXT(DATE($G$1,10,5),"d")&" "&CHOOSE(WEEKDAY(DATE($G$1,10,5),2),"Mo","Di","Mi","Do","Fr","Sa","So")&IFERROR(CHAR(10)&VLOOKUP(DATE($G$1,10,5),Feiertage!$A$2:$B$13,2,FALSE),""),"") -> d Mo | E45: =IF(MONTH(DATE($G$1,11,5))=11,TEXT(DATE($G$1,11,5),"d")&" "&CHOOSE(WEEKDAY(DATE($G$1,11,5),2),"Mo","Di","Mi","Do","Fr","Sa","So")&IFERROR(CHAR(10)&VLOOKUP(DATE($G$1,11,5),Feiertage!$A$2:$B$13,2,FALSE),""),"") -> d Do | F45: =IF(MONTH(DATE($G$1,12,5))=12,TEXT(DATE($G$1,12,5),"d")&" "&CHOOSE(WEEKDAY(DATE($G$1,12,5),2),"Mo","Di","Mi","Do","Fr","Sa","So")&IFERROR(CHAR(10)&VLOOKUP(DATE($G$1,12,5),Feiertage!$A$2:$B$13,2,FALSE),""),"") -> d Sa
A46: =IF(MONTH(DATE($G$1,7,6))=7,TEXT(DATE($G$1,7,6),"d")&" "&CHOOSE(WEEKDAY(DATE($G$1,7,6),2),"Mo","Di","Mi","Do","Fr","Sa","So")&IFERROR(CHAR(10)&VLOOKUP(DATE($G$1,7,6),Feiertage!$A$2:$B$13,2,FALSE),""),"") -> d Mo | B46: =IF(MONTH(DATE($G$1,8,6))=8,TEXT(DATE($G$1,8,6),"d")&" "&CHOOSE(WEEKDAY(DATE($G$1,8,6),2),"Mo","Di","Mi","Do","Fr","Sa","So")&IFERROR(CHAR(10)&VLOOKUP(DATE($G$1,8,6),Feiertage!$A$2:$B$13,2,FALSE),""),"") -> d Do | C46: =IF(MONTH(DATE($G$1,9,6))=9,TEXT(DATE($G$1,9,6),"d")&" "&CHOOSE(WEEKDAY(DATE($G$1,9,6),2),"Mo","Di","Mi","Do","Fr","Sa","So")&IFERROR(CHAR(10)&VLOOKUP(DATE($G$1,9,6),Feiertage!$A$2:$B$13,2,FALSE),""),"") -> d So | D46: =IF(MONTH(DATE($G$1,10,6))=10,TEXT(DATE($G$1,10,6),"d")&" "&CHOOSE(WEEKDAY(DATE($G$1,10,6),2),"Mo","Di","Mi","Do","Fr","Sa","So")&IFERROR(CHAR(10)&VLOOKUP(DATE($G$1,10,6),Feiertage!$A$2:$B$13,2,FALSE),""),"") -> d Di | E46: =IF(MONTH(DATE($G$1,11,6))=11,TEXT(DATE($G$1,11,6),"d")&" "&CHOOSE(WEEKDAY(DATE($G$1,11,6),2),"Mo","Di","Mi","Do","Fr","Sa","So")&IFERROR(CHAR(10)&VLOOKUP(DATE($G$1,11,6),Feiertage!$A$2:$B$13,2,FALSE),""),"") -> d Fr | F46: =IF(MONTH(DATE($G$1,12,6))=12,TEXT(DATE($G$1,12,6),"d")&" "&CHOOSE(WEEKDAY(DATE($G$1,12,6),2),"Mo","Di","Mi","Do","Fr","Sa","So")&IFERROR(CHAR(10)&VLOOKUP(DATE($G$1,12,6),Feiertage!$A$2:$B$13,2,FALSE),""),"") -> d So
...

Sheet Feiertage
A1: Datum | B1: Feiertag | D1: Ostersonntag (berechnet) | E1: =DATE(Kalender!$G$1,Q4,R4) -> 46117
A2: =DATE(Kalender!$G$1,1,1) -> 46023 | B2: Neujahr
A3: =$E$1-2 -> 46115 | B3: Karfreitag | E3: a | F3: b | G3: c | H3: d | I3: e | J3: f | K3: g | L3: h | M3: i | N3: k | O3: l | P3: m | Q3: Monat | R3: Tag
A4: =$E$1 -> 46117 | B4: Ostern | E4: =MOD(Kalender!$G$1,19) -> 12 | F4: =INT(Kalender!$G$1/100) -> 20 | G4: =MOD(Kalender!$G$1,100) -> 26 | H4: =INT(F4/4) -> 5 | I4: =MOD(F4,4) -> 0 | J4: =INT((F4+8)/25) -> 1 | K4: =INT((F4-J4+1)/3) -> 6 | L4: =MOD(19*E4+F4-H4-K4+15,30) -> 12 | M4: =INT(G4/4) -> 6 | N4: =MOD(G4,4) -> 2 | O4: =MOD(32+2*I4+2*M4-L4-N4,7) -> 2 | P4: =INT((E4+11*L4+22*O4)/451) -> 0 | Q4: =INT((L4+O4-7*P4+114)/31) -> 4 | R4: =MOD(L4+O4-7*P4+114,31)+1 -> 5
A5: =$E$1+1 -> 46118 | B5: Ostermontag
A6: =DATE(Kalender!$G$1,5,1) -> 46143 | B6: Tag der Arbeit
A7: =$E$1+39 -> 46156 | B7: Christi Himmelfahrt
A8: =$E$1+49 -> 46166 | B8: Pfingsten
A9: =$E$1+50 -> 46167 | B9: Pfingstmontag
A10: =DATE(Kalender!$G$1,10,3) -> 46298 | B10: Tag der Deutschen Einheit
A11: =DATE(Kalender!$G$1,10,31) -> 46326 | B11: Reformationstag (SH)
A12: =DATE(Kalender!$G$1,12,25) -> 46381 | B12: 1. Weihnachtstag
A13: =DATE(Kalender!$G$1,12,26) -> 46382 | B13: 2. Weihnachtstag
A15: Hinweis | B15: Feiertage sind für Schleswig-Holstein zusammengestellt; bitte bei Bedarf anpassen.
